// We expect this function to return 1;
(() => {
    try {
        return 1; // 1 is returned but suspended until finally block ends
    } catch(err) {
        return 2;
    } finally {
        return 3; // 3 is returned before 1, which we did not expect
    }
})();

// > 3
// We expect this function to throw an error, then return
(() => {
    try {
        throw new Error("Try"); // error is thrown but suspended until finally block ends
    } finally {
        return 3; // 3 is returned before the error is thrown, which we did not expect
    }
})();

// > 3
// We expect this function to throw Try(...) error from the catch block
(() => {
    try {
        throw new Error("Try")
    } catch(err) {
        throw err; // The error thrown from try block is catched and rethrown
    } finally {
        throw new Error("Finally"); // Finally(...) is thrown, which we did not expect
    }
})();

// > Uncaught Error: Finally(...)
// We expect this function to return 0 from try block.
(() => {
  label: try {
    return 0; // 1 is returned but suspended until finally block ends
  } finally {
    break label; // It breaks out the try-finally block, before 0 is returned.
  }
  return 1;
})();

// > 1
/*eslint no-unsafe-finally: "error"*/
let foo = function() {
    try {
        return 1;
    } catch(err) {
        return 2;
    } finally {
        return 3;
    }
};
/*eslint no-unsafe-finally: "error"*/
let foo = function() {
    try {
        return 1;
    } catch(err) {
        return 2;
    } finally {
        throw new Error;
    }
};
/*eslint no-unsafe-finally: "error"*/
let foo = function() {
    try {
        return 1;
    } catch(err) {
        return 2;
    } finally {
        console.log("hola!");
    }
};
/*eslint no-unsafe-finally: "error"*/
let foo = function() {
    try {
        return 1;
    } catch(err) {
        return 2;
    } finally {
        let a = function() {
            return "hola!";
        }
    }
};
/*eslint no-unsafe-finally: "error"*/
let foo = function(a) {
    try {
        return 1;
    } catch(err) {
        return 2;
    } finally {
        switch(a) {
            case 1: {
                console.log("hola!")
                break;
            }
        }
    }
};
